2018-04-19 00:54:27,031 ERROR: Exception on /favicon.ico [GET] [in C:\Users\Albert\Anaconda3\envs\microblog\lib\site-packages\flask\app.py:1560]
Traceback (most recent call last):
  File "C:\Users\Albert\Anaconda3\envs\microblog\lib\site-packages\flask\app.py", line 1612, in full_dispatch_request
    rv = self.dispatch_request()
  File "C:\Users\Albert\Anaconda3\envs\microblog\lib\site-packages\flask\app.py", line 1590, in dispatch_request
    self.raise_routing_exception(req)
  File "C:\Users\Albert\Anaconda3\envs\microblog\lib\site-packages\flask\app.py", line 1573, in raise_routing_exception
    raise request.routing_exception
  File "C:\Users\Albert\Anaconda3\envs\microblog\lib\site-packages\flask\ctx.py", line 294, in match_request
    self.url_adapter.match(return_rule=True)
  File "C:\Users\Albert\Anaconda3\envs\microblog\lib\site-packages\werkzeug\routing.py", line 1581, in match
    raise NotFound()
werkzeug.exceptions.NotFound: 404 Not Found: The requested URL was not found on the server.  If you entered the URL manually please check your spelling and try again.

During handling of the above exception, another exception occurred:

Traceback (most recent call last):
  File "C:\Users\Albert\Anaconda3\envs\microblog\lib\site-packages\flask\app.py", line 1982, in wsgi_app
    response = self.full_dispatch_request()
  File "C:\Users\Albert\Anaconda3\envs\microblog\lib\site-packages\flask\app.py", line 1614, in full_dispatch_request
    rv = self.handle_user_exception(e)
  File "C:\Users\Albert\Anaconda3\envs\microblog\lib\site-packages\flask\app.py", line 1512, in handle_user_exception
    return self.handle_http_exception(e)
  File "C:\Users\Albert\Anaconda3\envs\microblog\lib\site-packages\flask\app.py", line 1471, in handle_http_exception
    return handler(e)
  File "C:\Users\Albert\Documents\GitHub\microblog\app\errors.py", line 6, in not_found_error
    return render_template('404.html'), 404
  File "C:\Users\Albert\Anaconda3\envs\microblog\lib\site-packages\flask\templating.py", line 134, in render_template
    context, ctx.app)
  File "C:\Users\Albert\Anaconda3\envs\microblog\lib\site-packages\flask\templating.py", line 116, in _render
    rv = template.render(context)
  File "C:\Users\Albert\Anaconda3\envs\microblog\lib\site-packages\jinja2\asyncsupport.py", line 76, in render
    return original_render(self, *args, **kwargs)
  File "C:\Users\Albert\Anaconda3\envs\microblog\lib\site-packages\jinja2\environment.py", line 1008, in render
    return self.environment.handle_exception(exc_info, True)
  File "C:\Users\Albert\Anaconda3\envs\microblog\lib\site-packages\jinja2\environment.py", line 780, in handle_exception
    reraise(exc_type, exc_value, tb)
  File "C:\Users\Albert\Anaconda3\envs\microblog\lib\site-packages\jinja2\_compat.py", line 37, in reraise
    raise value.with_traceback(tb)
  File "C:\Users\Albert\Documents\GitHub\microblog\app\templates\404.html", line 1, in top-level template code
    {% extends "base.html" %}
  File "C:\Users\Albert\Documents\GitHub\microblog\app\templates\base.html", line 1, in top-level template code
    {% extends 'bootstrap/base.html' %}
  File "C:\Users\Albert\Anaconda3\envs\microblog\lib\site-packages\flask_bootstrap\templates\bootstrap\base.html", line 1, in top-level template code
    {% block doc -%}
  File "C:\Users\Albert\Anaconda3\envs\microblog\lib\site-packages\flask_bootstrap\templates\bootstrap\base.html", line 4, in block "doc"
    {%- block html %}
  File "C:\Users\Albert\Anaconda3\envs\microblog\lib\site-packages\flask_bootstrap\templates\bootstrap\base.html", line 6, in block "html"
    {%- block head %}
  File "C:\Users\Albert\Anaconda3\envs\microblog\lib\site-packages\flask_bootstrap\templates\bootstrap\base.html", line 7, in block "head"
    <title>{% block title %}{{title|default}}{% endblock title %}</title>
  File "C:\Users\Albert\Documents\GitHub\microblog\app\templates\base.html", line 4, in block "title"
    {% if title %}{{ title }} - Microblog{% else %}{{ _('Welcome to Microblog') }}{% endif %}
jinja2.exceptions.UndefinedError: '_' is undefined
2018-04-28 16:33:38,482 INFO: Microblog startup [in C:\Users\Albert\Documents\GitHub\microblog\app\__init__.py:48]
2018-04-28 16:33:48,138 ERROR: Exception on /login [GET] [in C:\Users\Albert\Anaconda3\envs\microblog\lib\site-packages\flask\app.py:1560]
Traceback (most recent call last):
  File "C:\Users\Albert\Anaconda3\envs\microblog\lib\site-packages\flask\app.py", line 1982, in wsgi_app
    response = self.full_dispatch_request()
  File "C:\Users\Albert\Anaconda3\envs\microblog\lib\site-packages\flask\app.py", line 1614, in full_dispatch_request
    rv = self.handle_user_exception(e)
  File "C:\Users\Albert\Anaconda3\envs\microblog\lib\site-packages\flask\app.py", line 1517, in handle_user_exception
    reraise(exc_type, exc_value, tb)
  File "C:\Users\Albert\Anaconda3\envs\microblog\lib\site-packages\flask\_compat.py", line 33, in reraise
    raise value
  File "C:\Users\Albert\Anaconda3\envs\microblog\lib\site-packages\flask\app.py", line 1612, in full_dispatch_request
    rv = self.dispatch_request()
  File "C:\Users\Albert\Anaconda3\envs\microblog\lib\site-packages\flask\app.py", line 1598, in dispatch_request
    return self.view_functions[rule.endpoint](**req.view_args)
  File "C:\Users\Albert\Documents\GitHub\microblog\app\routes.py", line 47, in login
    return render_template('login.html', title='Sign In', form=form)
  File "C:\Users\Albert\Anaconda3\envs\microblog\lib\site-packages\flask\templating.py", line 134, in render_template
    context, ctx.app)
  File "C:\Users\Albert\Anaconda3\envs\microblog\lib\site-packages\flask\templating.py", line 116, in _render
    rv = template.render(context)
  File "C:\Users\Albert\Anaconda3\envs\microblog\lib\site-packages\jinja2\asyncsupport.py", line 76, in render
    return original_render(self, *args, **kwargs)
  File "C:\Users\Albert\Anaconda3\envs\microblog\lib\site-packages\jinja2\environment.py", line 1008, in render
    return self.environment.handle_exception(exc_info, True)
  File "C:\Users\Albert\Anaconda3\envs\microblog\lib\site-packages\jinja2\environment.py", line 780, in handle_exception
    reraise(exc_type, exc_value, tb)
  File "C:\Users\Albert\Anaconda3\envs\microblog\lib\site-packages\jinja2\_compat.py", line 37, in reraise
    raise value.with_traceback(tb)
  File "C:\Users\Albert\Documents\GitHub\microblog\app\templates\login.html", line 2, in top-level template code
    {% import 'bootstrap/wtf.html' as wtf %}
  File "C:\Users\Albert\Documents\GitHub\microblog\app\templates\base.html", line 1, in top-level template code
    {% extends 'bootstrap/base.html' %}
  File "C:\Users\Albert\Anaconda3\envs\microblog\lib\site-packages\flask_bootstrap\templates\bootstrap\base.html", line 1, in top-level template code
    {% block doc -%}
  File "C:\Users\Albert\Anaconda3\envs\microblog\lib\site-packages\flask_bootstrap\templates\bootstrap\base.html", line 4, in block "doc"
    {%- block html %}
  File "C:\Users\Albert\Anaconda3\envs\microblog\lib\site-packages\flask_bootstrap\templates\bootstrap\base.html", line 20, in block "html"
    {% block body -%}
  File "C:\Users\Albert\Anaconda3\envs\microblog\lib\site-packages\flask_bootstrap\templates\bootstrap\base.html", line 21, in block "body"
    {% block navbar %}
  File "C:\Users\Albert\Documents\GitHub\microblog\app\templates\base.html", line 21, in block "navbar"
    <li><a href="{{ url_for('index') }}">{{ _('Home') }}</a></li>
jinja2.exceptions.UndefinedError: '_' is undefined
