2018-04-10 10:28:59,486 INFO: Microblog startup [in C:\Users\Albert\Documents\GitHub\microblog\app\__init__.py:44]
2018-04-10 10:29:05,554 INFO: Microblog startup [in C:\Users\Albert\Documents\GitHub\microblog\app\__init__.py:44]
2018-04-11 12:26:24,513 INFO: Microblog startup [in C:\Users\Albert\Documents\GitHub\microblog\app\__init__.py:44]
2018-04-11 12:26:38,606 INFO: Microblog startup [in C:\Users\Albert\Documents\GitHub\microblog\app\__init__.py:44]
2018-04-11 12:26:58,641 INFO: Microblog startup [in C:\Users\Albert\Documents\GitHub\microblog\app\__init__.py:44]
2018-04-11 12:40:57,947 INFO: Microblog startup [in C:\Users\Albert\Documents\GitHub\microblog\app\__init__.py:44]
2018-04-11 12:41:22,558 ERROR: Exception on /unfollow/susan [GET] [in C:\Users\Albert\Anaconda3\envs\microblog\lib\site-packages\flask\app.py:1560]
Traceback (most recent call last):
  File "C:\Users\Albert\Anaconda3\envs\microblog\lib\site-packages\flask\app.py", line 1982, in wsgi_app
    response = self.full_dispatch_request()
  File "C:\Users\Albert\Anaconda3\envs\microblog\lib\site-packages\flask\app.py", line 1614, in full_dispatch_request
    rv = self.handle_user_exception(e)
  File "C:\Users\Albert\Anaconda3\envs\microblog\lib\site-packages\flask\app.py", line 1517, in handle_user_exception
    reraise(exc_type, exc_value, tb)
  File "C:\Users\Albert\Anaconda3\envs\microblog\lib\site-packages\flask\_compat.py", line 33, in reraise
    raise value
  File "C:\Users\Albert\Anaconda3\envs\microblog\lib\site-packages\flask\app.py", line 1612, in full_dispatch_request
    rv = self.dispatch_request()
  File "C:\Users\Albert\Anaconda3\envs\microblog\lib\site-packages\flask\app.py", line 1598, in dispatch_request
    return self.view_functions[rule.endpoint](**req.view_args)
  File "C:\Users\Albert\Anaconda3\envs\microblog\lib\site-packages\flask_login\utils.py", line 261, in decorated_view
    return func(*args, **kwargs)
  File "C:\Users\Albert\Documents\GitHub\microblog\app\routes.py", line 119, in unfollow
    db.sessino.commit()
AttributeError: 'SQLAlchemy' object has no attribute 'sessino'
2018-04-11 13:13:42,038 INFO: Microblog startup [in C:\Users\Albert\Documents\GitHub\microblog\app\__init__.py:44]
2018-04-12 08:07:51,271 INFO: Microblog startup [in C:\Users\Albert\Documents\GitHub\microblog\app\__init__.py:44]
2018-04-12 08:20:06,753 INFO: Microblog startup [in C:\Users\Albert\Documents\GitHub\microblog\app\__init__.py:44]
2018-04-12 08:39:34,192 INFO: Microblog startup [in C:\Users\Albert\Documents\GitHub\microblog\app\__init__.py:44]
2018-04-12 08:39:51,531 ERROR: Exception on /user/albert [GET] [in C:\Users\Albert\Anaconda3\envs\microblog\lib\site-packages\flask\app.py:1560]
Traceback (most recent call last):
  File "C:\Users\Albert\Anaconda3\envs\microblog\lib\site-packages\flask\app.py", line 1982, in wsgi_app
    response = self.full_dispatch_request()
  File "C:\Users\Albert\Anaconda3\envs\microblog\lib\site-packages\flask\app.py", line 1614, in full_dispatch_request
    rv = self.handle_user_exception(e)
  File "C:\Users\Albert\Anaconda3\envs\microblog\lib\site-packages\flask\app.py", line 1517, in handle_user_exception
    reraise(exc_type, exc_value, tb)
  File "C:\Users\Albert\Anaconda3\envs\microblog\lib\site-packages\flask\_compat.py", line 33, in reraise
    raise value
  File "C:\Users\Albert\Anaconda3\envs\microblog\lib\site-packages\flask\app.py", line 1612, in full_dispatch_request
    rv = self.dispatch_request()
  File "C:\Users\Albert\Anaconda3\envs\microblog\lib\site-packages\flask\app.py", line 1598, in dispatch_request
    return self.view_functions[rule.endpoint](**req.view_args)
  File "C:\Users\Albert\Anaconda3\envs\microblog\lib\site-packages\flask_login\utils.py", line 261, in decorated_view
    return func(*args, **kwargs)
  File "C:\Users\Albert\Documents\GitHub\microblog\app\routes.py", line 77, in user
    next_url=next_url, prev_url=prev_url)
  File "C:\Users\Albert\Anaconda3\envs\microblog\lib\site-packages\flask\templating.py", line 134, in render_template
    context, ctx.app)
  File "C:\Users\Albert\Anaconda3\envs\microblog\lib\site-packages\flask\templating.py", line 116, in _render
    rv = template.render(context)
  File "C:\Users\Albert\Anaconda3\envs\microblog\lib\site-packages\jinja2\asyncsupport.py", line 76, in render
    return original_render(self, *args, **kwargs)
  File "C:\Users\Albert\Anaconda3\envs\microblog\lib\site-packages\jinja2\environment.py", line 1008, in render
    return self.environment.handle_exception(exc_info, True)
  File "C:\Users\Albert\Anaconda3\envs\microblog\lib\site-packages\jinja2\environment.py", line 780, in handle_exception
    reraise(exc_type, exc_value, tb)
  File "C:\Users\Albert\Anaconda3\envs\microblog\lib\site-packages\jinja2\_compat.py", line 37, in reraise
    raise value.with_traceback(tb)
  File "C:\Users\Albert\Documents\GitHub\microblog\app\templates\user.html", line 1, in top-level template code
    {% extends "base.html" %}
  File "C:\Users\Albert\Documents\GitHub\microblog\app\templates\base.html", line 30, in top-level template code
    {% block content %}{% endblock %}
  File "C:\Users\Albert\Documents\GitHub\microblog\app\templates\user.html", line 23, in block "content"
    {% for post in posts %}
TypeError: 'Pagination' object is not iterable
2018-04-12 08:41:56,470 INFO: Microblog startup [in C:\Users\Albert\Documents\GitHub\microblog\app\__init__.py:44]
2018-04-12 08:49:09,338 INFO: Microblog startup [in C:\Users\Albert\Documents\GitHub\microblog\app\__init__.py:46]
